[2023-04-13T20:03:53.363+0000] {taskinstance.py:1090} INFO - Dependencies all met for dep_context=non-requeueable deps ti=<TaskInstance: weather_dag.inject_data_Odesa manual__2023-04-13T20:03:41.496045+00:00 [queued]>
[2023-04-13T20:03:53.387+0000] {taskinstance.py:1090} INFO - Dependencies all met for dep_context=requeueable deps ti=<TaskInstance: weather_dag.inject_data_Odesa manual__2023-04-13T20:03:41.496045+00:00 [queued]>
[2023-04-13T20:03:53.388+0000] {taskinstance.py:1288} INFO - 
--------------------------------------------------------------------------------
[2023-04-13T20:03:53.390+0000] {taskinstance.py:1289} INFO - Starting attempt 1 of 1
[2023-04-13T20:03:53.394+0000] {taskinstance.py:1290} INFO - 
--------------------------------------------------------------------------------
[2023-04-13T20:03:53.418+0000] {taskinstance.py:1309} INFO - Executing <Task(SqliteOperator): inject_data_Odesa> on 2023-04-13 20:03:41.496045+00:00
[2023-04-13T20:03:53.429+0000] {standard_task_runner.py:55} INFO - Started process 6292 to run task
[2023-04-13T20:03:53.450+0000] {standard_task_runner.py:82} INFO - Running: ['***', 'tasks', 'run', 'weather_dag', 'inject_data_Odesa', 'manual__2023-04-13T20:03:41.496045+00:00', '--job-id', '264', '--raw', '--subdir', 'DAGS_FOLDER/weather_dag.py', '--cfg-path', '/tmp/tmpwn1yxcjg']
[2023-04-13T20:03:53.453+0000] {standard_task_runner.py:83} INFO - Job 264: Subtask inject_data_Odesa
[2023-04-13T20:03:53.569+0000] {task_command.py:389} INFO - Running <TaskInstance: weather_dag.inject_data_Odesa manual__2023-04-13T20:03:41.496045+00:00 [running]> on host ffea11fb791c
[2023-04-13T20:03:53.685+0000] {taskinstance.py:1518} INFO - Exporting the following env vars:
AIRFLOW_CTX_DAG_OWNER=***
AIRFLOW_CTX_DAG_ID=weather_dag
AIRFLOW_CTX_TASK_ID=inject_data_Odesa
AIRFLOW_CTX_EXECUTION_DATE=2023-04-13T20:03:41.496045+00:00
AIRFLOW_CTX_TRY_NUMBER=1
AIRFLOW_CTX_DAG_RUN_ID=manual__2023-04-13T20:03:41.496045+00:00
[2023-04-13T20:03:53.687+0000] {sql.py:254} INFO - Executing: 
                INSERT INTO measures_ext (timestamp, temp, humidity, cloudiness, wind_speed) VALUES
                    ({ti.xcom_pull(task_ids='transform_data_Odesa')[0]},
                    {ti.xcom_pull(task_ids='transform_data_Odesa')[1]},
                    {ti.xcom_pull(task_ids='transform_data_Odesa')[2]},
                    "{ti.xcom_pull(task_ids='transform_data_Odesa')[3]}",
                    {ti.xcom_pull(task_ids='transform_data_Odesa')[4]});
            
[2023-04-13T20:03:53.703+0000] {base.py:73} INFO - Using connection ID 'measure_db' for task execution.
[2023-04-13T20:03:54.082+0000] {base.py:73} INFO - Using connection ID 'measure_db' for task execution.
[2023-04-13T20:03:54.098+0000] {sql.py:375} INFO - Running statement: 
                INSERT INTO measures_ext (timestamp, temp, humidity, cloudiness, wind_speed) VALUES
                    ({ti.xcom_pull(task_ids='transform_data_Odesa')[0]},
                    {ti.xcom_pull(task_ids='transform_data_Odesa')[1]},
                    {ti.xcom_pull(task_ids='transform_data_Odesa')[2]},
                    "{ti.xcom_pull(task_ids='transform_data_Odesa')[3]}",
                    {ti.xcom_pull(task_ids='transform_data_Odesa')[4]});
            , parameters: None
[2023-04-13T20:03:54.102+0000] {taskinstance.py:1776} ERROR - Task failed with exception
Traceback (most recent call last):
  File "/home/airflow/.local/lib/python3.7/site-packages/airflow/providers/common/sql/operators/sql.py", line 266, in execute
    **extra_kwargs,
  File "/home/airflow/.local/lib/python3.7/site-packages/airflow/providers/common/sql/hooks/sql.py", line 349, in run
    self._run_command(cur, sql_statement, parameters)
  File "/home/airflow/.local/lib/python3.7/site-packages/airflow/providers/common/sql/hooks/sql.py", line 380, in _run_command
    cur.execute(sql_statement)
sqlite3.OperationalError: unrecognized token: "{"
[2023-04-13T20:03:54.125+0000] {taskinstance.py:1332} INFO - Marking task as FAILED. dag_id=weather_dag, task_id=inject_data_Odesa, execution_date=20230413T200341, start_date=20230413T200353, end_date=20230413T200354
[2023-04-13T20:03:54.146+0000] {standard_task_runner.py:105} ERROR - Failed to execute job 264 for task inject_data_Odesa (unrecognized token: "{"; 6292)
[2023-04-13T20:03:54.177+0000] {local_task_job.py:212} INFO - Task exited with return code 1
[2023-04-13T20:03:54.203+0000] {taskinstance.py:2596} INFO - 0 downstream tasks scheduled from follow-on schedule check
