[2023-04-14T03:39:14.261+0000] {taskinstance.py:1090} INFO - Dependencies all met for dep_context=non-requeueable deps ti=<TaskInstance: weather_dag.retrieve_weather_data_Kyiv scheduled__2023-04-14T02:00:00+00:00 [queued]>
[2023-04-14T03:39:14.325+0000] {taskinstance.py:1090} INFO - Dependencies all met for dep_context=requeueable deps ti=<TaskInstance: weather_dag.retrieve_weather_data_Kyiv scheduled__2023-04-14T02:00:00+00:00 [queued]>
[2023-04-14T03:39:14.327+0000] {taskinstance.py:1288} INFO - 
--------------------------------------------------------------------------------
[2023-04-14T03:39:14.328+0000] {taskinstance.py:1289} INFO - Starting attempt 1 of 1
[2023-04-14T03:39:14.329+0000] {taskinstance.py:1290} INFO - 
--------------------------------------------------------------------------------
[2023-04-14T03:39:14.362+0000] {taskinstance.py:1309} INFO - Executing <Task(SimpleHttpOperator): retrieve_weather_data_Kyiv> on 2023-04-14 02:00:00+00:00
[2023-04-14T03:39:14.373+0000] {standard_task_runner.py:55} INFO - Started process 7540 to run task
[2023-04-14T03:39:14.398+0000] {standard_task_runner.py:82} INFO - Running: ['***', 'tasks', 'run', 'weather_dag', 'retrieve_weather_data_Kyiv', 'scheduled__2023-04-14T02:00:00+00:00', '--job-id', '445', '--raw', '--subdir', 'DAGS_FOLDER/weather_dag.py', '--cfg-path', '/tmp/tmpgq1lxcyu']
[2023-04-14T03:39:14.402+0000] {standard_task_runner.py:83} INFO - Job 445: Subtask retrieve_weather_data_Kyiv
[2023-04-14T03:39:14.618+0000] {task_command.py:389} INFO - Running <TaskInstance: weather_dag.retrieve_weather_data_Kyiv scheduled__2023-04-14T02:00:00+00:00 [running]> on host ffea11fb791c
[2023-04-14T03:39:14.980+0000] {taskinstance.py:1518} INFO - Exporting the following env vars:
AIRFLOW_CTX_DAG_OWNER=***
AIRFLOW_CTX_DAG_ID=weather_dag
AIRFLOW_CTX_TASK_ID=retrieve_weather_data_Kyiv
AIRFLOW_CTX_EXECUTION_DATE=2023-04-14T02:00:00+00:00
AIRFLOW_CTX_TRY_NUMBER=1
AIRFLOW_CTX_DAG_RUN_ID=scheduled__2023-04-14T02:00:00+00:00
[2023-04-14T03:39:14.984+0000] {http.py:123} INFO - Calling HTTP method
[2023-04-14T03:39:15.021+0000] {base.py:73} INFO - Using connection ID 'weather_http_api' for task execution.
[2023-04-14T03:39:24.418+0000] {http.py:215} WARNING - ('Connection aborted.', OSError(0, 'Error')) Tenacity will retry to execute the operation
[2023-04-14T03:39:25.423+0000] {taskinstance.py:1776} ERROR - Task failed with exception
Traceback (most recent call last):
  File "/home/airflow/.local/lib/python3.7/site-packages/urllib3/connectionpool.py", line 710, in urlopen
    chunked=chunked,
  File "/home/airflow/.local/lib/python3.7/site-packages/urllib3/connectionpool.py", line 386, in _make_request
    self._validate_conn(conn)
  File "/home/airflow/.local/lib/python3.7/site-packages/urllib3/connectionpool.py", line 1042, in _validate_conn
    conn.connect()
  File "/home/airflow/.local/lib/python3.7/site-packages/urllib3/connection.py", line 429, in connect
    tls_in_tls=tls_in_tls,
  File "/home/airflow/.local/lib/python3.7/site-packages/urllib3/util/ssl_.py", line 450, in ssl_wrap_socket
    sock, context, tls_in_tls, server_hostname=server_hostname
  File "/home/airflow/.local/lib/python3.7/site-packages/urllib3/util/ssl_.py", line 493, in _ssl_wrap_socket_impl
    return ssl_context.wrap_socket(sock, server_hostname=server_hostname)
  File "/usr/local/lib/python3.7/ssl.py", line 423, in wrap_socket
    session=session
  File "/usr/local/lib/python3.7/ssl.py", line 870, in _create
    self.do_handshake()
  File "/usr/local/lib/python3.7/ssl.py", line 1139, in do_handshake
    self._sslobj.do_handshake()
OSError: [Errno 0] Error

During handling of the above exception, another exception occurred:

Traceback (most recent call last):
  File "/home/airflow/.local/lib/python3.7/site-packages/requests/adapters.py", line 499, in send
    timeout=timeout,
  File "/home/airflow/.local/lib/python3.7/site-packages/urllib3/connectionpool.py", line 788, in urlopen
    method, url, error=e, _pool=self, _stacktrace=sys.exc_info()[2]
  File "/home/airflow/.local/lib/python3.7/site-packages/urllib3/util/retry.py", line 550, in increment
    raise six.reraise(type(error), error, _stacktrace)
  File "/home/airflow/.local/lib/python3.7/site-packages/urllib3/packages/six.py", line 769, in reraise
    raise value.with_traceback(tb)
  File "/home/airflow/.local/lib/python3.7/site-packages/urllib3/connectionpool.py", line 710, in urlopen
    chunked=chunked,
  File "/home/airflow/.local/lib/python3.7/site-packages/urllib3/connectionpool.py", line 386, in _make_request
    self._validate_conn(conn)
  File "/home/airflow/.local/lib/python3.7/site-packages/urllib3/connectionpool.py", line 1042, in _validate_conn
    conn.connect()
  File "/home/airflow/.local/lib/python3.7/site-packages/urllib3/connection.py", line 429, in connect
    tls_in_tls=tls_in_tls,
  File "/home/airflow/.local/lib/python3.7/site-packages/urllib3/util/ssl_.py", line 450, in ssl_wrap_socket
    sock, context, tls_in_tls, server_hostname=server_hostname
  File "/home/airflow/.local/lib/python3.7/site-packages/urllib3/util/ssl_.py", line 493, in _ssl_wrap_socket_impl
    return ssl_context.wrap_socket(sock, server_hostname=server_hostname)
  File "/usr/local/lib/python3.7/ssl.py", line 423, in wrap_socket
    session=session
  File "/usr/local/lib/python3.7/ssl.py", line 870, in _create
    self.do_handshake()
  File "/usr/local/lib/python3.7/ssl.py", line 1139, in do_handshake
    self._sslobj.do_handshake()
urllib3.exceptions.ProtocolError: ('Connection aborted.', OSError(0, 'Error'))

During handling of the above exception, another exception occurred:

Traceback (most recent call last):
  File "/home/airflow/.local/lib/python3.7/site-packages/airflow/providers/http/operators/http.py", line 125, in execute
    response = http.run(self.endpoint, self.data, self.headers, self.extra_options)
  File "/home/airflow/.local/lib/python3.7/site-packages/airflow/providers/http/hooks/http.py", line 158, in run
    return self.run_and_check(session, prepped_request, extra_options)
  File "/home/airflow/.local/lib/python3.7/site-packages/airflow/providers/http/hooks/http.py", line 216, in run_and_check
    raise ex
  File "/home/airflow/.local/lib/python3.7/site-packages/airflow/providers/http/hooks/http.py", line 208, in run_and_check
    response = session.send(prepped_request, **send_kwargs)
  File "/home/airflow/.local/lib/python3.7/site-packages/requests/sessions.py", line 701, in send
    r = adapter.send(request, **kwargs)
  File "/home/airflow/.local/lib/python3.7/site-packages/requests/adapters.py", line 547, in send
    raise ConnectionError(err, request=request)
requests.exceptions.ConnectionError: ('Connection aborted.', OSError(0, 'Error'))
[2023-04-14T03:39:25.460+0000] {taskinstance.py:1332} INFO - Marking task as FAILED. dag_id=weather_dag, task_id=retrieve_weather_data_Kyiv, execution_date=20230414T020000, start_date=20230414T033914, end_date=20230414T033925
[2023-04-14T03:39:25.511+0000] {standard_task_runner.py:105} ERROR - Failed to execute job 445 for task retrieve_weather_data_Kyiv (('Connection aborted.', OSError(0, 'Error')); 7540)
[2023-04-14T03:39:25.559+0000] {local_task_job.py:212} INFO - Task exited with return code 1
[2023-04-14T03:39:26.592+0000] {taskinstance.py:2596} INFO - 0 downstream tasks scheduled from follow-on schedule check
