[2023-04-14T19:03:25.139+0000] {taskinstance.py:1090} INFO - Dependencies all met for dep_context=non-requeueable deps ti=<TaskInstance: weather_dag.retrieve_historical_weather_data_Kharkiv scheduled__2023-04-14T18:00:00+00:00 [queued]>
[2023-04-14T19:03:25.216+0000] {taskinstance.py:1090} INFO - Dependencies all met for dep_context=requeueable deps ti=<TaskInstance: weather_dag.retrieve_historical_weather_data_Kharkiv scheduled__2023-04-14T18:00:00+00:00 [queued]>
[2023-04-14T19:03:25.219+0000] {taskinstance.py:1288} INFO - 
--------------------------------------------------------------------------------
[2023-04-14T19:03:25.221+0000] {taskinstance.py:1289} INFO - Starting attempt 1 of 1
[2023-04-14T19:03:25.223+0000] {taskinstance.py:1290} INFO - 
--------------------------------------------------------------------------------
[2023-04-14T19:03:25.269+0000] {taskinstance.py:1309} INFO - Executing <Task(SimpleHttpOperator): retrieve_historical_weather_data_Kharkiv> on 2023-04-14 18:00:00+00:00
[2023-04-14T19:03:25.280+0000] {standard_task_runner.py:55} INFO - Started process 15495 to run task
[2023-04-14T19:03:25.292+0000] {standard_task_runner.py:82} INFO - Running: ['***', 'tasks', 'run', 'weather_dag', 'retrieve_historical_weather_data_Kharkiv', 'scheduled__2023-04-14T18:00:00+00:00', '--job-id', '590', '--raw', '--subdir', 'DAGS_FOLDER/weather_dag.py', '--cfg-path', '/tmp/tmpfn_2naaw']
[2023-04-14T19:03:25.295+0000] {standard_task_runner.py:83} INFO - Job 590: Subtask retrieve_historical_weather_data_Kharkiv
[2023-04-14T19:03:25.499+0000] {task_command.py:389} INFO - Running <TaskInstance: weather_dag.retrieve_historical_weather_data_Kharkiv scheduled__2023-04-14T18:00:00+00:00 [running]> on host ffea11fb791c
[2023-04-14T19:03:25.578+0000] {warnings.py:110} WARNING - /home/***/.local/lib/python3.7/site-packages/***/utils/context.py:205: AirflowContextDeprecationWarning: Accessing 'execution_date' from the template is deprecated and will be removed in a future version. Please use 'data_interval_start' or 'logical_date' instead.
  warnings.warn(_create_deprecation_warning(key, self._deprecation_replacements[key]))

[2023-04-14T19:03:25.731+0000] {taskinstance.py:1518} INFO - Exporting the following env vars:
AIRFLOW_CTX_DAG_OWNER=***
AIRFLOW_CTX_DAG_ID=weather_dag
AIRFLOW_CTX_TASK_ID=retrieve_historical_weather_data_Kharkiv
AIRFLOW_CTX_EXECUTION_DATE=2023-04-14T18:00:00+00:00
AIRFLOW_CTX_TRY_NUMBER=1
AIRFLOW_CTX_DAG_RUN_ID=scheduled__2023-04-14T18:00:00+00:00
[2023-04-14T19:03:25.734+0000] {http.py:123} INFO - Calling HTTP method
[2023-04-14T19:03:25.756+0000] {base.py:73} INFO - Using connection ID 'weather_http_api' for task execution.
[2023-04-14T19:03:26.129+0000] {http.py:170} ERROR - HTTP error: Unauthorized
[2023-04-14T19:03:26.131+0000] {http.py:171} ERROR - {"cod":401, "message": "Please note that using One Call 3.0 requires a separate subscription to the One Call by Call plan. Learn more here https://openweathermap.org/price. If you have a valid subscription to the One Call by Call plan, but still receive this error, then please see https://openweathermap.org/faq#error401 for more info."}
[2023-04-14T19:03:26.156+0000] {taskinstance.py:1776} ERROR - Task failed with exception
Traceback (most recent call last):
  File "/home/airflow/.local/lib/python3.7/site-packages/airflow/providers/http/hooks/http.py", line 168, in check_response
    response.raise_for_status()
  File "/home/airflow/.local/lib/python3.7/site-packages/requests/models.py", line 1021, in raise_for_status
    raise HTTPError(http_error_msg, response=self)
requests.exceptions.HTTPError: 401 Client Error: Unauthorized for url: https://api.openweathermap.org/data/3.0/onecall/timemachine?q=Kharkiv&appid=034a764f2b2c1c3fa00cbea1824b4e57&dt=1681495200

During handling of the above exception, another exception occurred:

Traceback (most recent call last):
  File "/home/airflow/.local/lib/python3.7/site-packages/airflow/providers/http/operators/http.py", line 125, in execute
    response = http.run(self.endpoint, self.data, self.headers, self.extra_options)
  File "/home/airflow/.local/lib/python3.7/site-packages/airflow/providers/http/hooks/http.py", line 158, in run
    return self.run_and_check(session, prepped_request, extra_options)
  File "/home/airflow/.local/lib/python3.7/site-packages/airflow/providers/http/hooks/http.py", line 211, in run_and_check
    self.check_response(response)
  File "/home/airflow/.local/lib/python3.7/site-packages/airflow/providers/http/hooks/http.py", line 172, in check_response
    raise AirflowException(str(response.status_code) + ":" + response.reason)
airflow.exceptions.AirflowException: 401:Unauthorized
[2023-04-14T19:03:26.170+0000] {taskinstance.py:1332} INFO - Marking task as FAILED. dag_id=weather_dag, task_id=retrieve_historical_weather_data_Kharkiv, execution_date=20230414T180000, start_date=20230414T190325, end_date=20230414T190326
[2023-04-14T19:03:26.225+0000] {standard_task_runner.py:105} ERROR - Failed to execute job 590 for task retrieve_historical_weather_data_Kharkiv (401:Unauthorized; 15495)
[2023-04-14T19:03:26.280+0000] {local_task_job.py:212} INFO - Task exited with return code 1
[2023-04-14T19:03:29.336+0000] {taskinstance.py:2596} INFO - 0 downstream tasks scheduled from follow-on schedule check
