[2023-04-13T20:03:54.500+0000] {taskinstance.py:1090} INFO - Dependencies all met for dep_context=non-requeueable deps ti=<TaskInstance: weather_dag.inject_data_Kyiv manual__2023-04-13T20:03:41.496045+00:00 [queued]>
[2023-04-13T20:03:54.511+0000] {taskinstance.py:1090} INFO - Dependencies all met for dep_context=requeueable deps ti=<TaskInstance: weather_dag.inject_data_Kyiv manual__2023-04-13T20:03:41.496045+00:00 [queued]>
[2023-04-13T20:03:54.512+0000] {taskinstance.py:1288} INFO - 
--------------------------------------------------------------------------------
[2023-04-13T20:03:54.513+0000] {taskinstance.py:1289} INFO - Starting attempt 1 of 1
[2023-04-13T20:03:54.514+0000] {taskinstance.py:1290} INFO - 
--------------------------------------------------------------------------------
[2023-04-13T20:03:54.527+0000] {taskinstance.py:1309} INFO - Executing <Task(SqliteOperator): inject_data_Kyiv> on 2023-04-13 20:03:41.496045+00:00
[2023-04-13T20:03:54.532+0000] {standard_task_runner.py:55} INFO - Started process 6296 to run task
[2023-04-13T20:03:54.535+0000] {standard_task_runner.py:82} INFO - Running: ['***', 'tasks', 'run', 'weather_dag', 'inject_data_Kyiv', 'manual__2023-04-13T20:03:41.496045+00:00', '--job-id', '267', '--raw', '--subdir', 'DAGS_FOLDER/weather_dag.py', '--cfg-path', '/tmp/tmpimo6b8ix']
[2023-04-13T20:03:54.537+0000] {standard_task_runner.py:83} INFO - Job 267: Subtask inject_data_Kyiv
[2023-04-13T20:03:54.607+0000] {task_command.py:389} INFO - Running <TaskInstance: weather_dag.inject_data_Kyiv manual__2023-04-13T20:03:41.496045+00:00 [running]> on host ffea11fb791c
[2023-04-13T20:03:54.671+0000] {taskinstance.py:1518} INFO - Exporting the following env vars:
AIRFLOW_CTX_DAG_OWNER=***
AIRFLOW_CTX_DAG_ID=weather_dag
AIRFLOW_CTX_TASK_ID=inject_data_Kyiv
AIRFLOW_CTX_EXECUTION_DATE=2023-04-13T20:03:41.496045+00:00
AIRFLOW_CTX_TRY_NUMBER=1
AIRFLOW_CTX_DAG_RUN_ID=manual__2023-04-13T20:03:41.496045+00:00
[2023-04-13T20:03:54.673+0000] {sql.py:254} INFO - Executing: 
                INSERT INTO measures_ext (timestamp, temp, humidity, cloudiness, wind_speed) VALUES
                    ({ti.xcom_pull(task_ids='transform_data_Kyiv')[0]},
                    {ti.xcom_pull(task_ids='transform_data_Kyiv')[1]},
                    {ti.xcom_pull(task_ids='transform_data_Kyiv')[2]},
                    "{ti.xcom_pull(task_ids='transform_data_Kyiv')[3]}",
                    {ti.xcom_pull(task_ids='transform_data_Kyiv')[4]});
            
[2023-04-13T20:03:54.683+0000] {base.py:73} INFO - Using connection ID 'measure_db' for task execution.
[2023-04-13T20:03:54.862+0000] {base.py:73} INFO - Using connection ID 'measure_db' for task execution.
[2023-04-13T20:03:54.868+0000] {sql.py:375} INFO - Running statement: 
                INSERT INTO measures_ext (timestamp, temp, humidity, cloudiness, wind_speed) VALUES
                    ({ti.xcom_pull(task_ids='transform_data_Kyiv')[0]},
                    {ti.xcom_pull(task_ids='transform_data_Kyiv')[1]},
                    {ti.xcom_pull(task_ids='transform_data_Kyiv')[2]},
                    "{ti.xcom_pull(task_ids='transform_data_Kyiv')[3]}",
                    {ti.xcom_pull(task_ids='transform_data_Kyiv')[4]});
            , parameters: None
[2023-04-13T20:03:54.869+0000] {taskinstance.py:1776} ERROR - Task failed with exception
Traceback (most recent call last):
  File "/home/airflow/.local/lib/python3.7/site-packages/airflow/providers/common/sql/operators/sql.py", line 266, in execute
    **extra_kwargs,
  File "/home/airflow/.local/lib/python3.7/site-packages/airflow/providers/common/sql/hooks/sql.py", line 349, in run
    self._run_command(cur, sql_statement, parameters)
  File "/home/airflow/.local/lib/python3.7/site-packages/airflow/providers/common/sql/hooks/sql.py", line 380, in _run_command
    cur.execute(sql_statement)
sqlite3.OperationalError: unrecognized token: "{"
[2023-04-13T20:03:54.878+0000] {taskinstance.py:1332} INFO - Marking task as FAILED. dag_id=weather_dag, task_id=inject_data_Kyiv, execution_date=20230413T200341, start_date=20230413T200354, end_date=20230413T200354
[2023-04-13T20:03:54.890+0000] {standard_task_runner.py:105} ERROR - Failed to execute job 267 for task inject_data_Kyiv (unrecognized token: "{"; 6296)
[2023-04-13T20:03:54.913+0000] {local_task_job.py:212} INFO - Task exited with return code 1
[2023-04-13T20:03:54.931+0000] {taskinstance.py:2596} INFO - 0 downstream tasks scheduled from follow-on schedule check
