[2023-04-13T20:03:53.418+0000] {taskinstance.py:1090} INFO - Dependencies all met for dep_context=non-requeueable deps ti=<TaskInstance: weather_dag.inject_data_Kharkiv manual__2023-04-13T20:03:41.496045+00:00 [queued]>
[2023-04-13T20:03:53.440+0000] {taskinstance.py:1090} INFO - Dependencies all met for dep_context=requeueable deps ti=<TaskInstance: weather_dag.inject_data_Kharkiv manual__2023-04-13T20:03:41.496045+00:00 [queued]>
[2023-04-13T20:03:53.441+0000] {taskinstance.py:1288} INFO - 
--------------------------------------------------------------------------------
[2023-04-13T20:03:53.442+0000] {taskinstance.py:1289} INFO - Starting attempt 1 of 1
[2023-04-13T20:03:53.444+0000] {taskinstance.py:1290} INFO - 
--------------------------------------------------------------------------------
[2023-04-13T20:03:53.478+0000] {taskinstance.py:1309} INFO - Executing <Task(SqliteOperator): inject_data_Kharkiv> on 2023-04-13 20:03:41.496045+00:00
[2023-04-13T20:03:53.489+0000] {standard_task_runner.py:55} INFO - Started process 6293 to run task
[2023-04-13T20:03:53.511+0000] {standard_task_runner.py:82} INFO - Running: ['***', 'tasks', 'run', 'weather_dag', 'inject_data_Kharkiv', 'manual__2023-04-13T20:03:41.496045+00:00', '--job-id', '265', '--raw', '--subdir', 'DAGS_FOLDER/weather_dag.py', '--cfg-path', '/tmp/tmpirme4k9v']
[2023-04-13T20:03:53.513+0000] {standard_task_runner.py:83} INFO - Job 265: Subtask inject_data_Kharkiv
[2023-04-13T20:03:53.634+0000] {task_command.py:389} INFO - Running <TaskInstance: weather_dag.inject_data_Kharkiv manual__2023-04-13T20:03:41.496045+00:00 [running]> on host ffea11fb791c
[2023-04-13T20:03:53.751+0000] {taskinstance.py:1518} INFO - Exporting the following env vars:
AIRFLOW_CTX_DAG_OWNER=***
AIRFLOW_CTX_DAG_ID=weather_dag
AIRFLOW_CTX_TASK_ID=inject_data_Kharkiv
AIRFLOW_CTX_EXECUTION_DATE=2023-04-13T20:03:41.496045+00:00
AIRFLOW_CTX_TRY_NUMBER=1
AIRFLOW_CTX_DAG_RUN_ID=manual__2023-04-13T20:03:41.496045+00:00
[2023-04-13T20:03:53.762+0000] {sql.py:254} INFO - Executing: 
                INSERT INTO measures_ext (timestamp, temp, humidity, cloudiness, wind_speed) VALUES
                    ({ti.xcom_pull(task_ids='transform_data_Kharkiv')[0]},
                    {ti.xcom_pull(task_ids='transform_data_Kharkiv')[1]},
                    {ti.xcom_pull(task_ids='transform_data_Kharkiv')[2]},
                    "{ti.xcom_pull(task_ids='transform_data_Kharkiv')[3]}",
                    {ti.xcom_pull(task_ids='transform_data_Kharkiv')[4]});
            
[2023-04-13T20:03:53.784+0000] {base.py:73} INFO - Using connection ID 'measure_db' for task execution.
[2023-04-13T20:03:54.190+0000] {base.py:73} INFO - Using connection ID 'measure_db' for task execution.
[2023-04-13T20:03:54.198+0000] {sql.py:375} INFO - Running statement: 
                INSERT INTO measures_ext (timestamp, temp, humidity, cloudiness, wind_speed) VALUES
                    ({ti.xcom_pull(task_ids='transform_data_Kharkiv')[0]},
                    {ti.xcom_pull(task_ids='transform_data_Kharkiv')[1]},
                    {ti.xcom_pull(task_ids='transform_data_Kharkiv')[2]},
                    "{ti.xcom_pull(task_ids='transform_data_Kharkiv')[3]}",
                    {ti.xcom_pull(task_ids='transform_data_Kharkiv')[4]});
            , parameters: None
[2023-04-13T20:03:54.204+0000] {taskinstance.py:1776} ERROR - Task failed with exception
Traceback (most recent call last):
  File "/home/airflow/.local/lib/python3.7/site-packages/airflow/providers/common/sql/operators/sql.py", line 266, in execute
    **extra_kwargs,
  File "/home/airflow/.local/lib/python3.7/site-packages/airflow/providers/common/sql/hooks/sql.py", line 349, in run
    self._run_command(cur, sql_statement, parameters)
  File "/home/airflow/.local/lib/python3.7/site-packages/airflow/providers/common/sql/hooks/sql.py", line 380, in _run_command
    cur.execute(sql_statement)
sqlite3.OperationalError: unrecognized token: "{"
[2023-04-13T20:03:54.217+0000] {taskinstance.py:1332} INFO - Marking task as FAILED. dag_id=weather_dag, task_id=inject_data_Kharkiv, execution_date=20230413T200341, start_date=20230413T200353, end_date=20230413T200354
[2023-04-13T20:03:54.234+0000] {standard_task_runner.py:105} ERROR - Failed to execute job 265 for task inject_data_Kharkiv (unrecognized token: "{"; 6293)
[2023-04-13T20:03:54.284+0000] {local_task_job.py:212} INFO - Task exited with return code 1
[2023-04-13T20:03:54.313+0000] {taskinstance.py:2596} INFO - 0 downstream tasks scheduled from follow-on schedule check
