[2023-04-14T18:16:46.348+0000] {taskinstance.py:1090} INFO - Dependencies all met for dep_context=non-requeueable deps ti=<TaskInstance: weather_dag.retrieve_historical_weather_data_Kharkiv scheduled__2023-04-14T16:00:00+00:00 [queued]>
[2023-04-14T18:16:46.489+0000] {taskinstance.py:1090} INFO - Dependencies all met for dep_context=requeueable deps ti=<TaskInstance: weather_dag.retrieve_historical_weather_data_Kharkiv scheduled__2023-04-14T16:00:00+00:00 [queued]>
[2023-04-14T18:16:46.491+0000] {taskinstance.py:1288} INFO - 
--------------------------------------------------------------------------------
[2023-04-14T18:16:46.494+0000] {taskinstance.py:1289} INFO - Starting attempt 1 of 1
[2023-04-14T18:16:46.496+0000] {taskinstance.py:1290} INFO - 
--------------------------------------------------------------------------------
[2023-04-14T18:16:46.592+0000] {taskinstance.py:1309} INFO - Executing <Task(SimpleHttpOperator): retrieve_historical_weather_data_Kharkiv> on 2023-04-14 16:00:00+00:00
[2023-04-14T18:16:46.627+0000] {standard_task_runner.py:55} INFO - Started process 15461 to run task
[2023-04-14T18:16:46.674+0000] {standard_task_runner.py:82} INFO - Running: ['***', 'tasks', 'run', 'weather_dag', 'retrieve_historical_weather_data_Kharkiv', 'scheduled__2023-04-14T16:00:00+00:00', '--job-id', '575', '--raw', '--subdir', 'DAGS_FOLDER/weather_dag.py', '--cfg-path', '/tmp/tmpe_qbamsb']
[2023-04-14T18:16:47.666+0000] {standard_task_runner.py:83} INFO - Job 575: Subtask retrieve_historical_weather_data_Kharkiv
[2023-04-14T18:16:47.967+0000] {task_command.py:389} INFO - Running <TaskInstance: weather_dag.retrieve_historical_weather_data_Kharkiv scheduled__2023-04-14T16:00:00+00:00 [running]> on host ffea11fb791c
[2023-04-14T18:16:48.077+0000] {warnings.py:110} WARNING - /home/***/.local/lib/python3.7/site-packages/***/utils/context.py:205: AirflowContextDeprecationWarning: Accessing 'execution_date' from the template is deprecated and will be removed in a future version. Please use 'data_interval_start' or 'logical_date' instead.
  warnings.warn(_create_deprecation_warning(key, self._deprecation_replacements[key]))

[2023-04-14T18:16:48.223+0000] {taskinstance.py:1518} INFO - Exporting the following env vars:
AIRFLOW_CTX_DAG_OWNER=***
AIRFLOW_CTX_DAG_ID=weather_dag
AIRFLOW_CTX_TASK_ID=retrieve_historical_weather_data_Kharkiv
AIRFLOW_CTX_EXECUTION_DATE=2023-04-14T16:00:00+00:00
AIRFLOW_CTX_TRY_NUMBER=1
AIRFLOW_CTX_DAG_RUN_ID=scheduled__2023-04-14T16:00:00+00:00
[2023-04-14T18:16:48.227+0000] {http.py:123} INFO - Calling HTTP method
[2023-04-14T18:16:48.251+0000] {base.py:73} INFO - Using connection ID 'weather_http_api' for task execution.
[2023-04-14T18:16:50.542+0000] {http.py:170} ERROR - HTTP error: Unauthorized
[2023-04-14T18:16:50.543+0000] {http.py:171} ERROR - {"cod":401, "message": "Please note that using One Call 3.0 requires a separate subscription to the One Call by Call plan. Learn more here https://openweathermap.org/price. If you have a valid subscription to the One Call by Call plan, but still receive this error, then please see https://openweathermap.org/faq#error401 for more info."}
[2023-04-14T18:16:50.557+0000] {taskinstance.py:1776} ERROR - Task failed with exception
Traceback (most recent call last):
  File "/home/airflow/.local/lib/python3.7/site-packages/airflow/providers/http/hooks/http.py", line 168, in check_response
    response.raise_for_status()
  File "/home/airflow/.local/lib/python3.7/site-packages/requests/models.py", line 1021, in raise_for_status
    raise HTTPError(http_error_msg, response=self)
requests.exceptions.HTTPError: 401 Client Error: Unauthorized for url: https://api.openweathermap.org/data/3.0/onecall/timemachine?q=Kharkiv&appid=034a764f2b2c1c3fa00cbea1824b4e57&dt=1681488000

During handling of the above exception, another exception occurred:

Traceback (most recent call last):
  File "/home/airflow/.local/lib/python3.7/site-packages/airflow/providers/http/operators/http.py", line 125, in execute
    response = http.run(self.endpoint, self.data, self.headers, self.extra_options)
  File "/home/airflow/.local/lib/python3.7/site-packages/airflow/providers/http/hooks/http.py", line 158, in run
    return self.run_and_check(session, prepped_request, extra_options)
  File "/home/airflow/.local/lib/python3.7/site-packages/airflow/providers/http/hooks/http.py", line 211, in run_and_check
    self.check_response(response)
  File "/home/airflow/.local/lib/python3.7/site-packages/airflow/providers/http/hooks/http.py", line 172, in check_response
    raise AirflowException(str(response.status_code) + ":" + response.reason)
airflow.exceptions.AirflowException: 401:Unauthorized
[2023-04-14T18:16:50.565+0000] {taskinstance.py:1332} INFO - Marking task as FAILED. dag_id=weather_dag, task_id=retrieve_historical_weather_data_Kharkiv, execution_date=20230414T160000, start_date=20230414T181646, end_date=20230414T181650
[2023-04-14T18:16:50.587+0000] {standard_task_runner.py:105} ERROR - Failed to execute job 575 for task retrieve_historical_weather_data_Kharkiv (401:Unauthorized; 15461)
[2023-04-14T18:16:50.644+0000] {local_task_job.py:212} INFO - Task exited with return code 1
[2023-04-14T18:16:53.742+0000] {taskinstance.py:2596} INFO - 0 downstream tasks scheduled from follow-on schedule check
