[2023-04-13T08:26:03.405+0000] {taskinstance.py:1090} INFO - Dependencies all met for dep_context=non-requeueable deps ti=<TaskInstance: weather_dag.inject_data manual__2023-04-13T08:26:01.183937+00:00 [queued]>
[2023-04-13T08:26:03.448+0000] {taskinstance.py:1090} INFO - Dependencies all met for dep_context=requeueable deps ti=<TaskInstance: weather_dag.inject_data manual__2023-04-13T08:26:01.183937+00:00 [queued]>
[2023-04-13T08:26:03.454+0000] {taskinstance.py:1288} INFO - 
--------------------------------------------------------------------------------
[2023-04-13T08:26:03.457+0000] {taskinstance.py:1289} INFO - Starting attempt 1 of 1
[2023-04-13T08:26:03.459+0000] {taskinstance.py:1290} INFO - 
--------------------------------------------------------------------------------
[2023-04-13T08:26:03.502+0000] {taskinstance.py:1309} INFO - Executing <Task(SqliteOperator): inject_data> on 2023-04-13 08:26:01.183937+00:00
[2023-04-13T08:26:03.510+0000] {standard_task_runner.py:55} INFO - Started process 2153 to run task
[2023-04-13T08:26:03.519+0000] {standard_task_runner.py:82} INFO - Running: ['***', 'tasks', 'run', 'weather_dag', 'inject_data', 'manual__2023-04-13T08:26:01.183937+00:00', '--job-id', '41', '--raw', '--subdir', 'DAGS_FOLDER/weather_dag.py', '--cfg-path', '/tmp/tmp72e5y4a1']
[2023-04-13T08:26:03.522+0000] {standard_task_runner.py:83} INFO - Job 41: Subtask inject_data
[2023-04-13T08:26:03.640+0000] {task_command.py:389} INFO - Running <TaskInstance: weather_dag.inject_data manual__2023-04-13T08:26:01.183937+00:00 [running]> on host 0607b07c4f39
[2023-04-13T08:26:03.749+0000] {abstractoperator.py:615} ERROR - Exception rendering Jinja template for task 'inject_data', field 'sql'. Template: "\n        INSERT INTO measures (timestamp, temp) VALUES\n        ({{ti.xcom_pull(task_ids='process_data')[0]}},\n        {{ti.xcom_pull(task_ids='process_data')[1]}});\n        "
Traceback (most recent call last):
  File "/home/airflow/.local/lib/python3.7/site-packages/airflow/models/abstractoperator.py", line 607, in _do_render_template_fields
    seen_oids,
  File "/home/airflow/.local/lib/python3.7/site-packages/airflow/models/abstractoperator.py", line 665, in render_template
    return render_template_to_string(template, context)
  File "/home/airflow/.local/lib/python3.7/site-packages/airflow/utils/helpers.py", line 288, in render_template_to_string
    return render_template(template, cast(MutableMapping[str, Any], context), native=False)
  File "/home/airflow/.local/lib/python3.7/site-packages/airflow/utils/helpers.py", line 283, in render_template
    return "".join(nodes)
  File "<template>", line 13, in root
  File "/home/airflow/.local/lib/python3.7/site-packages/jinja2/runtime.py", line 852, in _fail_with_undefined_error
    raise self._undefined_exception(self._undefined_message)
jinja2.exceptions.UndefinedError: None has no element 0
[2023-04-13T08:26:03.754+0000] {taskinstance.py:1776} ERROR - Task failed with exception
Traceback (most recent call last):
  File "/home/airflow/.local/lib/python3.7/site-packages/airflow/models/taskinstance.py", line 1383, in _run_raw_task
    self._execute_task_with_callbacks(context, test_mode)
  File "/home/airflow/.local/lib/python3.7/site-packages/airflow/models/taskinstance.py", line 1502, in _execute_task_with_callbacks
    task_orig = self.render_templates(context=context)
  File "/home/airflow/.local/lib/python3.7/site-packages/airflow/models/taskinstance.py", line 2123, in render_templates
    original_task.render_template_fields(context)
  File "/home/airflow/.local/lib/python3.7/site-packages/airflow/models/baseoperator.py", line 1179, in render_template_fields
    self._do_render_template_fields(self, self.template_fields, context, jinja_env, set())
  File "/home/airflow/.local/lib/python3.7/site-packages/airflow/utils/session.py", line 75, in wrapper
    return func(*args, session=session, **kwargs)
  File "/home/airflow/.local/lib/python3.7/site-packages/airflow/models/abstractoperator.py", line 607, in _do_render_template_fields
    seen_oids,
  File "/home/airflow/.local/lib/python3.7/site-packages/airflow/models/abstractoperator.py", line 665, in render_template
    return render_template_to_string(template, context)
  File "/home/airflow/.local/lib/python3.7/site-packages/airflow/utils/helpers.py", line 288, in render_template_to_string
    return render_template(template, cast(MutableMapping[str, Any], context), native=False)
  File "/home/airflow/.local/lib/python3.7/site-packages/airflow/utils/helpers.py", line 283, in render_template
    return "".join(nodes)
  File "<template>", line 13, in root
  File "/home/airflow/.local/lib/python3.7/site-packages/jinja2/runtime.py", line 852, in _fail_with_undefined_error
    raise self._undefined_exception(self._undefined_message)
jinja2.exceptions.UndefinedError: None has no element 0
[2023-04-13T08:26:03.787+0000] {taskinstance.py:1332} INFO - Marking task as FAILED. dag_id=weather_dag, task_id=inject_data, execution_date=20230413T082601, start_date=20230413T082603, end_date=20230413T082603
[2023-04-13T08:26:03.814+0000] {standard_task_runner.py:105} ERROR - Failed to execute job 41 for task inject_data (None has no element 0; 2153)
[2023-04-13T08:26:03.850+0000] {local_task_job.py:212} INFO - Task exited with return code 1
[2023-04-13T08:26:03.882+0000] {taskinstance.py:2596} INFO - 0 downstream tasks scheduled from follow-on schedule check
